Workbook

Sheet Résumé
A1: Mr Tovo — Suivi des tâches (19 → 23 octobre)
A2: Mode d'emploi : dans chaque onglet, choisir le Status (En cours / Fait) et la personne dans « Fait par » via les listes déroulantes. Vide = pas commencé. Ce résumé se met à jour tout seul.
A4: Page | B4: Total | C4: En cours | D4: Fait | E4: Avancement | F4: Armando | G4: Tsiky | H4: Miora | I4: Andriantsoa
A5: 1. Lancement | B5: =COUNTA('1. Lancement'!A2:A200) | C5: =COUNTIF('1. Lancement'!H2:H200,"En cours") | D5: =COUNTIF('1. Lancement'!H2:H200,"Fait") | E5: =IF(B5=0,0,D5/B5) | F5: =COUNTIFS('1. Lancement'!I2:I200,"Armando",'1. Lancement'!H2:H200,"Fait") | G5: =COUNTIFS('1. Lancement'!I2:I200,"Tsiky",'1. Lancement'!H2:H200,"Fait") | H5: =COUNTIFS('1. Lancement'!I2:I200,"Miora",'1. Lancement'!H2:H200,"Fait") | I5: =COUNTIFS('1. Lancement'!I2:I200,"Andriantsoa",'1. Lancement'!H2:H200,"Fait")
A6: 2. Socle & Charte | B6: =COUNTA('2. Socle & Charte'!A2:A200) | C6: =COUNTIF('2. Socle & Charte'!H2:H200,"En cours") | D6: =COUNTIF('2. Socle & Charte'!H2:H200,"Fait") | E6: =IF(B6=0,0,D6/B6) | F6: =COUNTIFS('2. Socle & Charte'!I2:I200,"Armando",'2. Socle & Charte'!H2:H200,"Fait") | G6: =COUNTIFS('2. Socle & Charte'!I2:I200,"Tsiky",'2. Socle & Charte'!H2:H200,"Fait") | H6: =COUNTIFS('2. Socle & Charte'!I2:I200,"Miora",'2. Socle & Charte'!H2:H200,"Fait") | I6: =COUNTIFS('2. Socle & Charte'!I2:I200,"Andriantsoa",'2. Socle & Charte'!H2:H200,"Fait")
A7: 3. Connexion & Comptes | B7: =COUNTA('3. Connexion & Comptes'!A2:A200) | C7: =COUNTIF('3. Connexion & Comptes'!H2:H200,"En cours") | D7: =COUNTIF('3. Connexion & Comptes'!H2:H200,"Fait") | E7: =IF(B7=0,0,D7/B7) | F7: =COUNTIFS('3. Connexion & Comptes'!I2:I200,"Armando",'3. Connexion & Comptes'!H2:H200,"Fait") | G7: =COUNTIFS('3. Connexion & Comptes'!I2:I200,"Tsiky",'3. Connexion & Comptes'!H2:H200,"Fait") | H7: =COUNTIFS('3. Connexion & Comptes'!I2:I200,"Miora",'3. Connexion & Comptes'!H2:H200,"Fait") | I7: =COUNTIFS('3. Connexion & Comptes'!I2:I200,"Andriantsoa",'3. Connexion & Comptes'!H2:H200,"Fait")
A8: 4. Besoins & Postes | B8: =COUNTA('4. Besoins & Postes'!A2:A200) | C8: =COUNTIF('4. Besoins & Postes'!H2:H200,"En cours") | D8: =COUNTIF('4. Besoins & Postes'!H2:H200,"Fait") | E8: =IF(B8=0,0,D8/B8) | F8: =COUNTIFS('4. Besoins & Postes'!I2:I200,"Armando",'4. Besoins & Postes'!H2:H200,"Fait") | G8: =COUNTIFS('4. Besoins & Postes'!I2:I200,"Tsiky",'4. Besoins & Postes'!H2:H200,"Fait") | H8: =COUNTIFS('4. Besoins & Postes'!I2:I200,"Miora",'4. Besoins & Postes'!H2:H200,"Fait") | I8: =COUNTIFS('4. Besoins & Postes'!I2:I200,"Andriantsoa",'4. Besoins & Postes'!H2:H200,"Fait")
A9: 5. Offres & Carrières | B9: =COUNTA('5. Offres & Carrières'!A2:A200) | C9: =COUNTIF('5. Offres & Carrières'!H2:H200,"En cours") | D9: =COUNTIF('5. Offres & Carrières'!H2:H200,"Fait") | E9: =IF(B9=0,0,D9/B9) | F9: =COUNTIFS('5. Offres & Carrières'!I2:I200,"Armando",'5. Offres & Carrières'!H2:H200,"Fait") | G9: =COUNTIFS('5. Offres & Carrières'!I2:I200,"Tsiky",'5. Offres & Carrières'!H2:H200,"Fait") | H9: =COUNTIFS('5. Offres & Carrières'!I2:I200,"Miora",'5. Offres & Carrières'!H2:H200,"Fait") | I9: =COUNTIFS('5. Offres & Carrières'!I2:I200,"Andriantsoa",'5. Offres & Carrières'!H2:H200,"Fait")
A10: 6. Candidatures & Entretiens | B10: =COUNTA('6. Candidatures & Entretiens'!A2:A200) | C10: =COUNTIF('6. Candidatures & Entretiens'!H2:H200,"En cours") | D10: =COUNTIF('6. Candidatures & Entretiens'!H2:H200,"Fait") | E10: =IF(B10=0,0,D10/B10) | F10: =COUNTIFS('6. Candidatures & Entretiens'!I2:I200,"Armando",'6. Candidatures & Entretiens'!H2:H200,"Fait") | G10: =COUNTIFS('6. Candidatures & Entretiens'!I2:I200,"Tsiky",'6. Candidatures & Entretiens'!H2:H200,"Fait") | H10: =COUNTIFS('6. Candidatures & Entretiens'!I2:I200,"Miora",'6. Candidatures & Entretiens'!H2:H200,"Fait") | I10: =COUNTIFS('6. Candidatures & Entretiens'!I2:I200,"Andriantsoa",'6. Candidatures & Entretiens'!H2:H200,"Fait")
A11: 7. Propositions & Embauche | B11: =COUNTA('7. Propositions & Embauche'!A2:A200) | C11: =COUNTIF('7. Propositions & Embauche'!H2:H200,"En cours") | D11: =COUNTIF('7. Propositions & Embauche'!H2:H200,"Fait") | E11: =IF(B11=0,0,D11/B11) | F11: =COUNTIFS('7. Propositions & Embauche'!I2:I200,"Armando",'7. Propositions & Embauche'!H2:H200,"Fait") | G11: =COUNTIFS('7. Propositions & Embauche'!I2:I200,"Tsiky",'7. Propositions & Embauche'!H2:H200,"Fait") | H11: =COUNTIFS('7. Propositions & Embauche'!I2:I200,"Miora",'7. Propositions & Embauche'!H2:H200,"Fait") | I11: =COUNTIFS('7. Propositions & Embauche'!I2:I200,"Andriantsoa",'7. Propositions & Embauche'!H2:H200,"Fait")
A12: 8. Employés & Contrats | B12: =COUNTA('8. Employés & Contrats'!A2:A200) | C12: =COUNTIF('8. Employés & Contrats'!H2:H200,"En cours") | D12: =COUNTIF('8. Employés & Contrats'!H2:H200,"Fait") | E12: =IF(B12=0,0,D12/B12) | F12: =COUNTIFS('8. Employés & Contrats'!I2:I200,"Armando",'8. Employés & Contrats'!H2:H200,"Fait") | G12: =COUNTIFS('8. Employés & Contrats'!I2:I200,"Tsiky",'8. Employés & Contrats'!H2:H200,"Fait") | H12: =COUNTIFS('8. Employés & Contrats'!I2:I200,"Miora",'8. Employés & Contrats'!H2:H200,"Fait") | I12: =COUNTIFS('8. Employés & Contrats'!I2:I200,"Andriantsoa",'8. Employés & Contrats'!H2:H200,"Fait")
A13: 9. Onboarding | B13: =COUNTA('9. Onboarding'!A2:A200) | C13: =COUNTIF('9. Onboarding'!H2:H200,"En cours") | D13: =COUNTIF('9. Onboarding'!H2:H200,"Fait") | E13: =IF(B13=0,0,D13/B13) | F13: =COUNTIFS('9. Onboarding'!I2:I200,"Armando",'9. Onboarding'!H2:H200,"Fait") | G13: =COUNTIFS('9. Onboarding'!I2:I200,"Tsiky",'9. Onboarding'!H2:H200,"Fait") | H13: =COUNTIFS('9. Onboarding'!I2:I200,"Miora",'9. Onboarding'!H2:H200,"Fait") | I13: =COUNTIFS('9. Onboarding'!I2:I200,"Andriantsoa",'9. Onboarding'!H2:H200,"Fait")
A14: 10. Tableau de bord & Notifs | B14: =COUNTA('10. Tableau de bord & Notifs'!A2:A200) | C14: =COUNTIF('10. Tableau de bord & Notifs'!H2:H200,"En cours") | D14: =COUNTIF('10. Tableau de bord & Notifs'!H2:H200,"Fait") | E14: =IF(B14=0,0,D14/B14) | F14: =COUNTIFS('10. Tableau de bord & Notifs'!I2:I200,"Armando",'10. Tableau de bord & Notifs'!H2:H200,"Fait") | G14: =COUNTIFS('10. Tableau de bord & Notifs'!I2:I200,"Tsiky",'10. Tableau de bord & Notifs'!H2:H200,"Fait") | H14: =COUNTIFS('10. Tableau de bord & Notifs'!I2:I200,"Miora",'10. Tableau de bord & Notifs'!H2:H200,"Fait") | I14: =COUNTIFS('10. Tableau de bord & Notifs'!I2:I200,"Andriantsoa",'10. Tableau de bord & Notifs'!H2:H200,"Fait")
A15: 11. Tests & Soutenance | B15: =COUNTA('11. Tests & Soutenance'!A2:A200) | C15: =COUNTIF('11. Tests & Soutenance'!H2:H200,"En cours") | D15: =COUNTIF('11. Tests & Soutenance'!H2:H200,"Fait") | E15: =IF(B15=0,0,D15/B15) | F15: =COUNTIFS('11. Tests & Soutenance'!I2:I200,"Armando",'11. Tests & Soutenance'!H2:H200,"Fait") | G15: =COUNTIFS('11. Tests & Soutenance'!I2:I200,"Tsiky",'11. Tests & Soutenance'!H2:H200,"Fait") | H15: =COUNTIFS('11. Tests & Soutenance'!I2:I200,"Miora",'11. Tests & Soutenance'!H2:H200,"Fait") | I15: =COUNTIFS('11. Tests & Soutenance'!I2:I200,"Andriantsoa",'11. Tests & Soutenance'!H2:H200,"Fait")
A16: TOTAL | B16: =SUM(B5:B15) | C16: =SUM(C5:C15) | D16: =SUM(D5:D15) | E16: =IF(B16=0,0,D16/B16) | F16: =SUM(F5:F15) | G16: =SUM(G5:G15) | H16: =SUM(H5:H15) | I16: =SUM(I5:I15)
A18: Colonnes par personne = nombre de tâches « Fait » attribuées à cette personne.

Sheet Dossiers
A1: Où mettre les fichiers
A2: Abréviations de la colonne « Dossier / fichiers » : java/ = src/main/java/com/mrtovo/ · templates/ = src/main/resources/templates/ · static/ = src/main/resources/static/ · test/ = src/test/java/com/mrtovo/ · resources/ = src/main/resources/. Chaque dossier a un seul propriétaire : pour modifier le fichier d'un autre, on lui demande.
A4: Dossier / fichier | B4: Contenu (noms des fichiers) | C4: Propriétaire
A5: JAVA — src/main/java/com/mrtovo/
A6: MrTovoApplication.java | B6: Point d'entrée (existe déjà) | C6: BK0
A7: commun/config/ | B7: SecurityConfig.java | C7: BK0
A8: commun/entity/ | B8: EntiteBase, Compte, Role, Notification, Document, JournalAudit | C8: BK0
A9: commun/repository/ | B9: Un …Repository.java par entité | C9: BK0
A10: commun/service/ | B10: CompteDetailsService, StockageFichierService, NotificationService, AuditService, TableauDeBordService | C10: BK0
A11: commun/controller/ | B11: AuthController, DocumentController, NotificationController, TableauDeBordController, ErreurControllerAdvice, UtilisateurConnecteAdvice | C11: BK0
A12: commun/workflow/ | B12: Transition, MoteurStatuts, TransitionInterditeException | C12: BK0
A13: commun/demo/ | B13: DonneesReference, DonneesDemoCommun | C13: BK0
A14: besoin/entity/ | B14: Departement, ServiceDepartement, Poste, Besoin, TypeBesoin, StatutBesoin, Validation | C14: BK1
A15: besoin/repository/ | B15: Un …Repository.java par entité | C15: BK1
A16: besoin/service/ | B16: PosteService, BesoinService, BesoinWorkflow, OuvertureRecrutementService | C16: BK1
A17: besoin/controller/ | B17: PosteController, BesoinController, DepartementController | C17: BK1
... A36: onboarding/demo/ | B36: DonneesDemoOnboarding | C36: BK3
A37: TEMPLATES — src/main/resources/templates/
A38: fragments/ | B38: layout, entete, menu, pied, composants, frise, stepper, progression, formats | C38: FR0
A39: auth/ | B39: connexion, inscription | C39: FR0
A40: erreurs/ | B40: 403, 404, 500 | C40: FR0
A41: dashboard/ | B41: accueil | C41: FR0
A42: notifications/ | B42: liste | C42: FR0
A43: besoins/ | B43: liste, formulaire, detail | C43: FR0
A44: postes/ | B44: liste, detail, formulaire | C44: FR0
A45: departements/ | B45: liste, detail | C45: FR0
A46: admin/ | B46: comptes, audit (P3) | C46: FR0
A47: public/ | B47: layout-public, accueil, offres, offre-detail, confirmation | C47: FR1
A48: espace-candidat/ | B48: candidatures, proposition | C48: FR1
A49: offres/ | B49: liste, detail, formulaire | C49: FR1
... A57: onboarding/ | B57: checklist, mes-taches, modeles (P3) | C57: FR2
A58: STATIC — src/main/resources/static/
A59: css/style.css | B59: Charte, variables, styles communs | C59: FR0
A60: css/recrutement.css | B60: Pages publiques et recrutement | C60: FR1
A61: css/rh.css | B61: Employés, contrats, onboarding | C61: FR2
A62: js/app.js | B62: Script commun (confirmation, anti double clic, formulaire de besoin) | C62: FR0
A63: js/recrutement.js | B63: Contrôle du CV | C63: FR1
A64: RESSOURCES — src/main/resources/
A65: application.properties | B65: Config MySQL commune (existe déjà) | C65: BK0
A66: application-dev.properties | B66: Base mr_tovo, données de démo | C66: BK0
...

Sheet 1. Lancement
A1: ID | B1: Équipe | C1: Tâche | D1: Détails (faisable sans attendre personne) | E1: Dossier / fichiers | F1: Priorité | G1: Jour conseillé | H1: Status | I1: Fait par
A2: T-01 | B2: Tous | C2: Cloner et lancer le projet en local | D2: Installer MySQL en local (base mr_tovo créée automatiquement), régler DB_USERNAME / DB_PASSWORD si besoin, lancer ./mvnw spring-boot:run, vérifier que la page d'accueil répond. | E2: README.md (lecture) resources/application.properties (DB_USERNAME / DB_PASSWORD) | F2: P1 | G2: Lundi 9h
A3: T-02 | B3: Tous | C3: Compléter le MCD (objets ✏️) | D3: Compléter dans Figma ET dans TODO.md section 2 : Offre, Candidature, Proposition, Statut_…, Compte, Candidat, Validation, Entretien, Evaluation_Candidat, Onboarding, Onboarding_Tache, Document. Partir des champs proposés dans TODO.md. | E3: Figma : board « userflow » (MCD) TODO.md section 2 | F3: P1 | G3: Lundi 9h
A4: T-03 | B4: Tous | C4: Trancher circuit du besoin, statuts et rôles | D4: Décider Finance seule ou Finance + Direction, ajouter « terminé » à Statut_Contrat ou non, liste des rôles. Écrire la décision dans TODO.md sections 3 et 4. | E4: TODO.md sections 3 et 4 | F4: P1 | G4: Lundi 9h
A5: T-04 | B5: Tous | C5: Valider le contrat d'interface Back ↔ Front | D5: Relire TODO.md section 7 (URL, templates, noms des données) et valider tel quel ou corriger. | E5: TODO.md section 7 Feuille : onglet « Dossiers » | F5: P1 | G5: Lundi 9h
A6: T-05 | B6: Tous | C6: Décisions techniques | D6: Base MySQL (déjà configurée), schéma auto-généré (ddl-auto=update), Bootstrap, format du matricule (ex. AAAA0001), comptes de démo (même mot de passe). Écrire dans TODO.md. | E6: TODO.md section 6 (T-05) | F6: P1 | G6: Lundi 9h
A7: T-07 | B7: Tous | C7: Règles Git | D7: Branche main protégée, une branche par tâche nommée avec l'ID, PR relue par une personne, fusion avant 17h30. | E7: Réglages du dépôt GitHub (protection de main) | F7: P1 | G7: Lundi 9h
A8: T-08 | B8: Tous | C8: Groupe de discussion de l'équipe | D8: Créer le groupe et y partager le lien de cette feuille et du Figma. | E8: — | F8: P1 | G8: Lundi 9h

Sheet 2. Socle & Charte
A1: ID | B1: Équipe | C1: Tâche | D1: Détails (faisable sans attendre personne) | E1: Dossier / fichiers | F1: Priorité | G1: Jour conseillé | H1: Status | I1: Fait par
A2: BK0-01 | B2: Back | C2: Socle technique (pom, config, packages) | D2: MySQL + JPA déjà en place. Ajouter dans pom.xml : Spring Security, Thymeleaf extras. Profils dev (base mr_tovo) / test (base mr_tovo_test séparée). Un package vide par domaine. Classe de base des entités (id, dates, auteur). Sécurité ouverte temporairement. | E2: pom.xml resources/application.properties resources/application-dev.properties resources/application-test.properties java/commun/entity/EntiteBase.java java/commun/config/SecurityConfig.java (tout ouvert) Dossiers vides (+ .gitkeep) : java/{commun, besoin, recrutement, embauche, onboarding}/{entity, repository, service, controller, dto, demo}/ Déplacer java/controller/HomeController.java → java/recrutement/controller/PublicController.java | F2: P1 | G2: Lundi matin
A3: BK0-02 | B3: Back | C3: Entités communes + données de démo | D3: Entités Compte, Rôle, Notification, Document, Journal_Audit. Chargeur de données de démo (un fichier par domaine, profil dev). Valeurs des tables Statut_… et Type_…. Comptes : admin, rh, finance, manager1, manager2, employé, candidat1. | E3: java/commun/entity/Compte.java, Role.java, Notification.java, Document.java, JournalAudit.java java/commun/repository/CompteRepository.java, RoleRepository.java, NotificationRepository.java, DocumentRepository.java, JournalAuditRepository.java java/commun/demo/DonneesReference.java (valeurs Statut_… et Type_…) java/commun/demo/DonneesDemoCommun.java (comptes de démo) | F3: P1 | G3: Lundi après-midi
A4: BK0-03 | B4: Back | C4: Moteur de statuts commun | D4: Déclarer « de → vers, par rôle, condition », refuser les transitions non prévues avec un message clair, calculer actionsPossibles. Expliquer l'usage en 5 lignes dans le README. Testable seul avec un objet factice. | E4: java/commun/workflow/Transition.java java/commun/workflow/MoteurStatuts.java java/commun/workflow/TransitionInterditeException.java test/commun/workflow/MoteurStatutsTests.java README.md (section « Moteur de statuts ») | F4: P1 | G4: Lundi soir
A5: BK0-05 | B5: Back | C5: Stockage des fichiers (GED) | D5: Service autonome : dossier configuré hors Git, nom unique, PDF/images/Word, 5 Mo max, téléchargement /documents/{id}. Tester avec un upload de test. | E5: java/commun/service/StockageFichierService.java java/commun/controller/DocumentController.java (/documents/{id}) resources/application.properties (mrtovo.fichiers.dossier) | F5: P1 | G5: Mardi
A6: BK0-06 | B6: Back | C6: Gestion des erreurs | D6: Contrôleur d'erreurs vers erreurs/403, 404, 500 (créer des templates minimaux s'ils n'existent pas). Messages de validation en français, aucune trace technique visible. | E6: java/commun/controller/ErreurControllerAdvice.java resources/messages.properties (messages de validation en français) | F6: P1 | G6: Mardi
A7: DS1-01 | B7: Design | C7: Mini-charte graphique | D7: Palette (principale, secondaire, fond, texte, succès, alerte, erreur, info), typographie, espacements, icônes. Compatible Bootstrap. | E7: Figma : page « Charte » | F7: P1 | G7: Lundi matin
A8: DS1-02 | B8: Design | C8: Code couleur des statuts | D8: Tableau statut → couleur → libellé : brouillon gris, en attente bleu, à compléter orange, validé vert, refusé rouge, clôturé gris foncé. | E8: Figma : page « Charte » (tableau des statuts) | F8: P1 | G8: Lundi matin
A9: DS1-03 | B9: Design | C9: Gabarit de page | D9: En-tête (logo Mr Tovo, utilisateur, cloche, déconnexion), menu latéral par rôle, zone de contenu. Version ordinateur et mobile. | E9: Figma : page « Gabarit » | F9: P1 | G9: Lundi après-midi
A10: DS1-06 | B10: Design | C10: Bibliothèque de composants | D10: Boutons, champs avec erreur, badge de statut, tableau filtres + pagination, fenêtre de confirmation, flash, fil d'Ariane, frise, stepper, barre de progression, état vide. Chaque état. | E10: Figma : page « Composants » | F10: P1 | G10: Mardi matin
A11: FR0-01 | B11: Front | C11: Gabarit commun Thymeleaf | D11: Bootstrap, en-tête, menu latéral (en dur), contenu, pied de page, menu mobile repliable. Dans templates/fragments/. | E11: templates/fragments/layout.html (existe déjà) templates/fragments/entete.html templates/fragments/menu.html templates/fragments/pied.html static/css/style.css static/js/app.js | F11: P1 | G11: Lundi matin
A12: FR0-02 | B12: Front | C12: Variables CSS + fragments réutilisables | D12: Couleurs Bootstrap par défaut si la charte n'est pas prête (on remplacera les valeurs). Fragments : badge statut, flash succes/erreur, champ avec erreur, pagination, fil d'Ariane, état vide, confirmation avec commentaire. 2 lignes d'usage par fragment dans le README. | E12: static/css/style.css (variables :root) templates/fragments/composants.html (badgeStatut, flash, champ, pagination, filAriane, etatVide, confirmation) README.md (section « Fragments ») | F12: P1 | G12: Lundi après-midi
A13: FR0-03 | B13: Front | C13: Fragments frise, stepper, barre de progression | D13: Fragments autonomes avec données d'exemple, réutilisables par toutes les pages. | E13: templates/fragments/frise.html templates/fragments/stepper.html templates/fragments/progression.html | F13: P1 | G13: Lundi après-midi
A14: FR0-08 | B14: Front | C14: Formats français + script commun | D14: Dates jj/mm/aaaa, montants 1 234,56 €, confirmation avant action irréversible, bouton désactivé après clic. | E14: templates/fragments/formats.html (date, montant) static/js/app.js (confirmation, anti double clic) | F14: P1 | G14: Mercredi

Sheet 3. Connexion & Comptes
A1: ID | B1: Équipe | C1: Tâche | D1: Détails (faisable sans attendre personne) | E1: Dossier / fichiers | F1: Priorité | G1: Jour conseillé | H1: Status | I1: Fait par
A2: DS1-03b | B2: Design | C2: Maquettes connexion et inscription | D2: Écran de connexion à deux entrées (employé : matricule / candidat : identifiant) + création de compte candidat. | E2: Figma : page « Connexion » | F2: P1 | G2: Lundi après-midi
A3: BK0-04 | B3: Back | C3: Connexion à deux entrées + inscription candidat | D3: Employé (matricule + mdp) et candidat (identifiant + mdp), /inscription, mots de passe chiffrés, utilisateur connecté dispo partout. Protéger les URL par rôle (section 4), laisser publics /, /connexion, /inscription, /carrieres/**, CSS/JS/images. Prévenir l'équipe à l'activation. | E3: java/commun/config/SecurityConfig.java java/commun/service/CompteDetailsService.java java/commun/controller/AuthController.java (/connexion, /inscription) java/commun/dto/InscriptionFormulaire.java java/commun/controller/UtilisateurConnecteAdvice.java (utilisateur sur toutes les pages) | F3: P1 | G3: Mardi
A4: FR0-04 | B4: Front | C4: Pages connexion, inscription, erreurs | D4: auth/connexion (2 entrées, message identifiants faux, message après déconnexion), auth/inscription, erreurs/403, 404, 500. Données d'exemple dans le template. | E4: templates/auth/connexion.html templates/auth/inscription.html templates/erreurs/403.html, 404.html, 500.html | F4: P1 | G4: Mardi matin
A5: FR0-06 | B5: Front | C5: Menu par rôle + utilisateur dans l'en-tête | D5: Afficher les entrées du menu selon le rôle (sec:authorize), nom/rôle et déconnexion. Fonctionne même sans sécurité active (tout s'affiche). | E5: templates/fragments/menu.html templates/fragments/entete.html | F5: P1 | G5: Mardi
A6: BK0-11 | B6: Back | C6: Admin : gestion des comptes | D6: Page /admin/comptes, e-mails simulés dans les logs, tâche quotidienne (offres/propositions expirées, fin de contrat). | E6: java/commun/controller/AdminCompteController.java java/commun/service/EmailSimuleService.java java/commun/service/TachesPlanifiees.java templates/admin/comptes.html, templates/admin/audit.html | F6: P3 | G6: Si temps

Sheet 4. Besoins & Postes
A1: ID | B1: Équipe | C1: Tâche | D1: Détails (faisable sans attendre personne) | E1: Dossier / fichiers | F1: Priorité | G1: Jour conseillé | H1: Status | I1: Fait par
A2: DS1-04 | B2: Design | C2: Basse fidélité bloc 1 | D2: Liste des besoins, formulaire (création poste / recherche personnel), détail avec stepper Manager → RH → Finance → Ouverture, fenêtre de refus, liste des postes. | E2: Figma : page « Bloc 1 — basse fidélité » | F2: P1 | G2: Lundi après-midi
A3: DS1-07 | B3: Design | C3: Haute fidélité bloc 1 | D3: Partir de la basse fidélité DS1-04 et de la charte. | E3: Figma : page « Bloc 1 — haute fidélité » | F3: P1 | G3: Mardi après-midi
A4: BK1-01 | B4: Back | C4: Entités du bloc 1 | D4: Departement, Service, Poste, Besoin, Type_Besoin, Statut_Besoin, Validation avec les champs du MCD. | E4: java/besoin/entity/Departement.java, ServiceDepartement.java (table service), Poste.java, Besoin.java, TypeBesoin.java, StatutBesoin.java, Validation.java java/besoin/repository/DepartementRepository.java, ServiceDepartementRepository.java, PosteRepository.java, BesoinRepository.java, TypeBesoinRepository.java, StatutBesoinRepository.java, ValidationRepository.java | F4: P1 | G4: Lundi après-midi
A5: BK1-02 | B5: Back | C5: Données de démo du bloc 1 | D5: 4 départements × 2 services, ~15 postes (occupés / libres, estManager), 4 besoins à des statuts différents. | E5: java/besoin/demo/DonneesDemoBesoin.java | F5: P1 | G5: Lundi soir
A6: BK1-03 | B6: Back | C6: Contrôleurs postes et besoins (lecture) | D6: /postes (filtres département/service/occupé), /besoins (manager : son département, RH/Finance : tout), /besoins/{id} avec historique des validations. | E6: java/besoin/controller/PosteController.java (/postes) java/besoin/controller/BesoinController.java (/besoins, /besoins/{id}) java/besoin/service/PosteService.java java/besoin/service/BesoinService.java | F6: P1 | G6: Mardi matin
A7: BK1-04 | B7: Back | C7: Créer / modifier un besoin | D7: Validation : effectif ≥ 1, date future, budget > 0, motif obligatoire. Création poste → poste inactif et libre. Recherche personnel → poste existant libre. | E7: java/besoin/controller/BesoinController.java (/besoins/nouveau, /besoins/{id}/modifier) java/besoin/dto/BesoinFormulaire.java java/besoin/service/BesoinService.java | F7: P1 | G7: Mardi après-midi
A8: BK1-05 | B8: Back | C8: Workflow du besoin | D8: Envoyer RH, envoyer Finance, valider / refuser (commentaire), compléter, annuler. Chaque décision = une Validation. Fournir actionsPossibles. Si le moteur commun n'est pas prêt, coder les transitions en dur puis migrer. | E8: java/besoin/service/BesoinWorkflow.java java/besoin/controller/BesoinController.java (actions /envoyer-rh, /envoyer-finance, /valider, /refuser, /completer, /annuler) | F8: P1 | G8: Mercredi matin
A9: BK1-06 | B9: Back | C9: Ouverture du recrutement | D9: Besoin → recrutement ouvert, poste actif, création d'une Offre brouillon pré-remplie (titre, département, type de contrat). | E9: java/besoin/service/OuvertureRecrutementService.java (utilise recrutement/repository/OffreRepository) java/besoin/controller/BesoinController.java (/ouvrir-recrutement) | F9: P1 | G9: Mercredi après-midi
A10: BK1-07 | B10: Back | C10: Notifications du bloc 1 | D10: Envoyé RH → RH ; envoyé Finance → Finance ; retour Finance → manager et RH. Si le service de notif n'existe pas : log. | E10: java/besoin/service/BesoinWorkflow.java (appels à commun/service/NotificationService) | F10: P2 | G10: Mercredi
A11: BK1-09 | B11: Back | C11: Fiche poste + CRUD postes/services/départements | D11: Historique des titulaires via Historique_Employe. | E11: java/besoin/controller/DepartementController.java java/besoin/controller/PosteController.java (/postes/{id}, /nouveau, /modifier) java/besoin/dto/PosteFormulaire.java | F11: P2 | G11: Jeudi
A12: FR0-05 | B12: Front | C12: Pages du bloc 1 (statique) | D12: besoins/liste, besoins/formulaire (partie poste selon le type, petit script), besoins/detail (stepper + historique), fenêtre refus/complément, postes/liste. Données d'exemple. | E12: templates/besoins/liste.html templates/besoins/formulaire.html templates/besoins/detail.html templates/postes/liste.html static/js/app.js (bascule création poste / recherche personnel) | F12: P1 | G12: Mardi
A13: FR0-07 | B13: Front | C13: Brancher les pages du bloc 1 | D13: Remplacer les données d'exemple par les variables du contrat d'interface (besoins, besoin, formulaire, actionsPossibles). Boutons affichés seulement si dans actionsPossibles. | E13: templates/besoins/liste.html, formulaire.html, detail.html templates/postes/liste.html | F13: P1 | G13: Mercredi
A14: FR0-12 | B14: Front | C14: Fiche poste, formulaires poste/département | D14: Pages postes/detail, postes/formulaire, departements/liste et detail. | E14: templates/postes/detail.html, postes/formulaire.html templates/departements/liste.html, departements/detail.html templates/notifications/liste.html | F14: P2 | G14: Si temps

Sheet 5. Offres & Carrières
A1: ID | B1: Équipe | C1: Tâche | D1: Détails (faisable sans attendre personne) | E1: Dossier / fichiers | F1: Priorité | G1: Jour conseillé | H1: Status | I1: Fait par
A2: DS2-02 | B2: Design | C2: Basse fidélité offres + pages publiques | D2: Accueil public, liste des offres avec filtre, détail, « Candidater » → connexion / création compte → formulaire CV → confirmation, espace candidat, côté RH : liste/détail/modif des offres. | E2: Figma : page « Bloc 2 — basse fidélité » | F2: P1 | G2: Lundi après-midi
A3: DS2-04 | B3: Design | C3: Haute fidélité bloc 2 (carrières d'abord) | D3: Page carrières publique très soignée et parfaite sur mobile. | E3: Figma : page « Bloc 2 — haute fidélité » | F3: P1 | G3: Mardi
A4: BK2-01 | B4: Back | C4: Entités du bloc 2 | D4: Offre, Statut_Offre, Candidat (lié au Compte), Candidature, Statut_Candidature, Entretien, Evaluation_Candidat. | E4: java/recrutement/entity/Offre.java, StatutOffre.java, Candidat.java, Candidature.java, StatutCandidature.java, Entretien.java, EvaluationCandidat.java java/recrutement/repository/OffreRepository.java, StatutOffreRepository.java, CandidatRepository.java, CandidatureRepository.java, StatutCandidatureRepository.java, EntretienRepository.java, EvaluationCandidatRepository.java | F4: P1 | G4: Lundi après-midi
A5: BK2-02 | B5: Back | C5: Données de démo du bloc 2 | D5: 2 offres publiées, ~10 candidats avec compte (un qui a postulé à 2 offres), candidatures à différents statuts, entretiens, évaluations. | E5: java/recrutement/demo/DonneesDemoRecrutement.java | F5: P1 | G5: Lundi soir
A6: BK2-03 | B6: Back | C6: Offres côté RH | D6: /offres liste, détail, modif brouillon, publier, clôturer, annuler. | E6: java/recrutement/controller/OffreController.java (/offres…) java/recrutement/service/OffreService.java java/recrutement/service/OffreWorkflow.java java/recrutement/dto/OffreFormulaire.java | F6: P1 | G6: Mardi matin
A7: BK2-04 | B7: Back | C7: Candidature publique + espace candidat | D7: Offres publiées visibles sans connexion (/ et /carrieres), « Candidater » demande connexion ou compte, formulaire + CV (si la GED n'est pas prête, enregistrer sans fichier), une seule candidature par offre, /carrieres/merci, /espace-candidat. | E7: java/recrutement/controller/PublicController.java (/, /carrieres, /carrieres/{id}, /postuler, /merci) java/recrutement/controller/EspaceCandidatController.java (/espace-candidat) java/recrutement/service/CandidatureService.java java/recrutement/dto/CandidatureFormulaire.java | F7: P1 | G7: Mardi après-midi
A8: FR1-01 | B8: Front | C8: Pages publiques (statique) | D8: public/accueil, public/offres, public/offre-detail, public/confirmation avec gabarit public propre (logo, sans menu interne). Données d'exemple. | E8: templates/public/layout-public.html templates/public/accueil.html (remplace templates/index.html) templates/public/offres.html templates/public/offre-detail.html templates/public/confirmation.html static/css/recrutement.css | F8: P1 | G8: Lundi matin
A9: FR1-02 | B9: Front | C9: Pages RH des offres (statique) | D9: offres/liste (statut, nb de candidatures), offres/detail, offres/formulaire. Données d'exemple. | E9: templates/offres/liste.html templates/offres/detail.html templates/offres/formulaire.html | F9: P1 | G9: Lundi après-midi
A10: FR1-05 | B10: Front | C10: Finition page carrières + contrôle du CV | D10: Style soigné, mobile impeccable, vérification format/taille du CV côté navigateur. | E10: templates/public/offres.html, public/offre-detail.html static/css/recrutement.css static/js/recrutement.js (contrôle format / taille du CV) | F10: P1 | G10: Mardi
A11: FR1-11 | B11: Front | C11: Espace candidat | D11: espace-candidat/candidatures : offre, date, badge, lien, message si vide. « Candidater » renvoie vers connexion/inscription si non connecté. | E11: templates/espace-candidat/candidatures.html | F11: P1 | G11: Mercredi
A12: FR1-06 | B12: Front | C12: Brancher offres, carrières, candidatures | D12: Variables du contrat d'interface (offres, offre, formulaire, actionsPossibles). | E12: templates/offres/*.html templates/public/*.html templates/candidatures/liste.html, candidatures/detail.html | F12: P1 | G12: Mercredi

Sheet 6. Candidatures & Entretiens
A1: ID | B1: Équipe | C1: Tâche | D1: Détails (faisable sans attendre personne) | E1: Dossier / fichiers | F1: Priorité | G1: Jour conseillé | H1: Status | I1: Fait par
A2: DS2-06 | B2: Design | C2: Écrans P2 recrutement | D2: Fiche candidat, comparaison des évaluations, récapitulatif après acceptation, réponse à la proposition côté candidat. | E2: Figma : page « Bloc 2 — P2 » | F2: P2 | G2: Mercredi
A3: BK2-05 | B3: Back | C3: Workflow de la candidature | D3: Présélectionner, rejeter (motif), en entretien (auto au 1er entretien), retenir. Liste par offre + fiche avec actionsPossibles. | E3: java/recrutement/controller/CandidatureController.java (/offres/{id}/candidatures, /candidatures/{id}…) java/recrutement/service/CandidatureWorkflow.java | F3: P1 | G3: Mercredi matin
A4: BK2-06 | B4: Back | C4: Entretiens et évaluations | D4: Planifier (date future, ≥ 1 évaluateur, pas de conflit de créneau), réalisé, annulé. Évaluation : évaluateur assigné seulement, une par évaluateur/entretien, note moyenne. | E4: java/recrutement/controller/EntretienController.java java/recrutement/controller/EvaluationController.java java/recrutement/service/EntretienService.java java/recrutement/service/EvaluationService.java java/recrutement/dto/EntretienFormulaire.java, EvaluationFormulaire.java | F4: P1 | G4: Mercredi après-midi
A5: BK2-08 | B5: Back | C5: Fiche candidat, comparaison, notifications | D5: Toutes les candidatures d'un candidat, données de comparaison, notif candidature reçue / entretien planifié. | E5: java/recrutement/controller/CandidatController.java (/candidats/{id}) java/recrutement/controller/EvaluationController.java (/offres/{id}/comparaison) | F5: P2 | G5: Jeudi
A6: BK2-09 | B6: Back | C6: Kanban, agenda, anti-spam | D6: Candidatures par statut, agenda des entretiens, limite anti-spam. | E6: java/recrutement/controller/CandidatureController.java (?vue=kanban) java/recrutement/controller/EntretienController.java (/entretiens) | F6: P3 | G6: Si temps
A7: FR1-03 | B7: Front | C7: Pages candidatures (statique) | D7: candidatures/liste (badges, filtres), candidatures/detail (infos, CV, entretiens, évaluations, note moyenne, boutons, rejet avec motif). | E7: templates/candidatures/liste.html templates/candidatures/detail.html | F7: P1 | G7: Mardi matin
A8: FR1-04 | B8: Front | C8: Formulaires entretien et évaluation (statique) | D8: entretiens/formulaire (type, date, heure, lieu/visio, évaluateurs), evaluations/formulaire (critères, avis, points forts/faibles). | E8: templates/entretiens/formulaire.html templates/evaluations/formulaire.html | F8: P1 | G8: Mardi après-midi
A9: FR1-07 | B9: Front | C9: Brancher entretiens et évaluations | D9: Afficher aussi les erreurs de validation renvoyées par le Back. | E9: templates/entretiens/formulaire.html templates/evaluations/formulaire.html | F9: P1 | G9: Jeudi matin
A10: FR1-09 | B10: Front | C10: Fiche candidat + comparaison | D10: candidats/detail, evaluations/comparaison. | E10: templates/candidats/detail.html templates/evaluations/comparaison.html | F10: P2 | G10: Si temps
A11: FR1-10 | B11: Front | C11: Vue Kanban + agenda | D11: candidatures/kanban, entretiens/agenda. | E11: templates/candidatures/kanban.html templates/entretiens/agenda.html | F11: P3 | G11: Si temps

Sheet 7. Propositions & Embauche
A1: ID | B1: Équipe | C1: Tâche | D1: Détails (faisable sans attendre personne) | E1: Dossier / fichiers | F1: Priorité | G1: Jour conseillé | H1: Status | I1: Fait par
A2: DS2-03 | B2: Design | C2: Basse fidélité bloc 3 | D2: Formulaire de proposition, détail avec « accepte / refuse », liste des employés, dossier salarié en onglets. | E2: Figma : page « Bloc 3 — basse fidélité » | F2: P1 | G2: Lundi après-midi
A3: DS2-05 | B3: Design | C3: Haute fidélité bloc 3 | D3: Partir de DS2-03 et de la charte. | E3: Figma : page « Bloc 3 — haute fidélité » | F3: P1 | G3: Mercredi matin
A4: BK3-01 | B4: Back | C4: Entités blocs 3 et 4 | D4: Proposition, Statut_Proposition, Employe, Contrat, Statut_Contrat, Type_Contrat, Historique_Employe, Onboarding, Onboarding_Tache. | E4: java/embauche/entity/Proposition.java, StatutProposition.java, Employe.java, Contrat.java, StatutContrat.java, TypeContrat.java, HistoriqueEmploye.java java/embauche/repository/…Repository.java (un par entité) java/onboarding/entity/Onboarding.java, OnboardingTache.java java/onboarding/repository/OnboardingRepository.java, OnboardingTacheRepository.java | F4: P1 | G4: Lundi après-midi
A5: BK3-05 | B5: Back | C5: Proposition d'embauche + matricule | D5: Créer pour une candidature retenue seulement, envoyer, réponse accepte/refuse (motif). Matricule unique jamais réutilisé. | E5: java/embauche/controller/PropositionController.java (/candidatures/{id}/proposition, /propositions/{id}…) java/embauche/service/PropositionService.java java/embauche/service/MatriculeService.java java/embauche/dto/PropositionFormulaire.java | F5: P1 | G5: Mercredi matin
A6: BK3-06 | B6: Back | C6: Processus d'embauche (tout ou rien) | D6: À l'acceptation, en une transaction : Employe + matricule + lien candidat, Contrat « créé », poste occupé, actuels remplis + ligne d'historique, Onboarding + tâches, candidature embauchée, offre pourvue, redirection dossier. | E6: java/embauche/service/EmbaucheService.java (@Transactional) | F6: P1 | G6: Mercredi après-midi
A7: BK3-09 | B7: Back | C7: Récapitulatif, changement de poste, réponse candidat | D7: Récap après acceptation, changement de poste (+ historique), justificatifs, réponse depuis l'espace candidat, mes tâches, notifications. | E7: java/embauche/controller/PropositionController.java (/recapitulatif) java/embauche/controller/EmployeController.java (/changer-poste) java/embauche/controller/PropositionCandidatController.java (/espace-candidat/propositions/{id}) java/onboarding/controller/OnboardingController.java (/mes-taches) | F7: P2 | G7: Jeudi
A8: FR2-05 | B8: Front | C8: Pages proposition (statique) | D8: propositions/formulaire (salaire, date début, type, date limite), propositions/detail (accepte / refuse avec motif). | E8: templates/propositions/formulaire.html templates/propositions/detail.html static/css/rh.css | F8: P1 | G8: Mardi
A9: FR2-07 | B9: Front | C9: Brancher proposition + acceptation | D9: Après acceptation, arriver sur le dossier du nouvel employé. | E9: templates/propositions/detail.html templates/onboarding/checklist.html | F9: P1 | G9: Jeudi matin
A10: FR2-09 | B10: Front | C10: Récap, documents, changement de poste | D10: propositions/recapitulatif, onglet Documents avec upload, employes/changer-poste, mes tâches. | E10: templates/propositions/recapitulatif.html templates/employes/changer-poste.html templates/employes/dossier.html (onglet Documents) templates/onboarding/mes-taches.html templates/espace-candidat/proposition.html (dossier de FR1 : prévenir FR1) | F10: P2 | G10: Si temps

Sheet 8. Employés & Contrats
A1: ID | B1: Équipe | C1: Tâche | D1: Détails (faisable sans attendre personne) | E1: Dossier / fichiers | F1: Priorité | G1: Jour conseillé | H1: Status | I1: Fait par
A2: DS1-05 | B2: Design | C2: Basse fidélité bloc 4 | D2: Onglet contrats (frise CE → CDD → CDI), onglet historique, formulaire contrat (date de fin masquée pour CDI). | E2: Figma : page « Bloc 4 — basse fidélité » | F2: P1 | G2: Lundi après-midi
A3: DS1-08 | B3: Design | C3: Haute fidélité bloc 4 | D3: Partir de DS1-05 et de la charte. | E3: Figma : page « Bloc 4 — haute fidélité » | F3: P1 | G3: Mercredi matin
A4: BK3-02 | B4: Back | C4: Données de démo blocs 3 et 4 | D4: 6 tâches d'onboarding par défaut, 3 employés dont un CE → CDD → CDI (3 contrats + 3 lignes d'historique), un onboarding à moitié fait. | E4: java/embauche/demo/DonneesDemoEmbauche.java java/onboarding/demo/DonneesDemoOnboarding.java | F4: P1 | G4: Lundi soir
A5: BK3-03 | B5: Back | C5: Liste des employés + dossier salarié | D5: /employes (recherche nom/matricule), /employes/{id}?onglet=… avec identité, contrats, historique, documents, onboarding, origine. | E5: java/embauche/controller/EmployeController.java (/employes, /employes/{id}) java/embauche/service/EmployeService.java | F5: P1 | G5: Mardi matin
A6: BK3-04 | B6: Back | C6: Contrats | D6: Nouveau, signer, valider, annuler, rompre (motif). Renouvellement / CDI = nouveau contrat lié au précédent. Signé = non modifiable. Un seul validé, pas de chevauchement. CE/CDD : date de fin obligatoire. | E6: java/embauche/controller/ContratController.java (/employes/{id}/contrats/nouveau, /contrats/{id}…) java/embauche/service/ContratService.java java/embauche/service/ContratWorkflow.java java/embauche/dto/ContratFormulaire.java | F6: P1 | G6: Mardi après-midi
A7: FR2-01 | B7: Front | C7: Dossier salarié en onglets (statique) | D7: employes/dossier : Identité · Contrats · Historique · Documents · Onboarding · Origine, onglet selon ?onglet=. Données d'exemple. | E7: templates/employes/dossier.html static/css/rh.css | F7: P1 | G7: Lundi matin
A8: FR2-02 | B8: Front | C8: Liste des employés (statique) | D8: employes/liste : recherche nom/matricule, filtres département/statut. | E8: templates/employes/liste.html | F8: P1 | G8: Lundi après-midi
A9: FR2-03 | B9: Front | C9: Onglet Contrats + formulaire contrat | D9: Frise des contrats, contrat validé en avant, badges. contrats/formulaire (nouveau / renouvellement / CDI), date de fin masquée pour CDI. | E9: templates/employes/dossier.html (onglet Contrats) templates/contrats/formulaire.html | F9: P1 | G9: Mardi matin
A10: FR2-06 | B10: Front | C10: Brancher employés, dossier, contrats | D10: Variables du contrat d'interface (employes, employe, formulaire, actionsPossibles). | E10: templates/employes/liste.html templates/employes/dossier.html templates/contrats/formulaire.html | F10: P1 | G10: Mercredi

Sheet 9. Onboarding
A1: ID | B1: Équipe | C1: Tâche | D1: Détails (faisable sans attendre personne) | E1: Dossier / fichiers | F1: Priorité | G1: Jour conseillé | H1: Status | I1: Fait par
A2: BK3-07 | B2: Back | C2: Onboarding | D2: Changer le statut d'une tâche (responsable + RH), progression, fin auto quand tout est fait / non applicable. « Contrat signé » cochable seulement si le contrat est signé. | E2: java/onboarding/controller/OnboardingController.java (/onboardings/{id}, /onboarding-taches/{id}/statut) java/onboarding/service/OnboardingService.java | F2: P1 | G2: Jeudi matin
A3: BK3-10 | B3: Back | C3: Modèles de tâches + alerte fin de contrat | D3: Modèles modifiables par les RH. | E3: java/onboarding/entity/ModeleTache.java java/onboarding/repository/ModeleTacheRepository.java java/onboarding/controller/ModeleOnboardingController.java (/admin/modeles-onboarding) | F3: P3 | G3: Si temps
A4: FR2-04 | B4: Front | C4: Checklist d'onboarding + onglet Historique | D4: onboarding/checklist : tâches par catégorie, responsable, échéance, statut, barre de progression, retards en rouge. Onglet Historique du dossier. | E4: templates/onboarding/checklist.html templates/employes/dossier.html (onglet Historique) | F4: P1 | G4: Mardi après-midi
A5: FR2-10 | B5: Front | C5: Page modèles de tâches | D5: onboarding/modeles. | E5: templates/onboarding/modeles.html | F5: P3 | G5: Si temps

Sheet 10. Tableau de bord & Notifs
A1: ID | B1: Équipe | C1: Tâche | D1: Détails (faisable sans attendre personne) | E1: Dossier / fichiers | F1: Priorité | G1: Jour conseillé | H1: Status | I1: Fait par
A2: DS1-09 | B2: Design | C2: Tableau de bord, notifications, erreurs | D2: Dashboard Manager / RH / Finance, panneau notifications, pages 403/404/500. | E2: Figma : page « Tableau de bord » | F2: P2 | G2: Mercredi après-midi
A3: BK0-07 | B3: Back | C3: Service de notifications | D3: Notifier en une ligne, compteur de non lues partout, /notifications, marquer comme lu. | E3: java/commun/service/NotificationService.java java/commun/controller/NotificationController.java (/notifications) java/commun/controller/UtilisateurConnecteAdvice.java (compteur non lues) | F3: P2 | G3: Mercredi matin
A4: BK0-08 | B4: Back | C4: Journal d'audit automatique | D4: Écrire une ligne à chaque changement de statut (dans le moteur de statuts). | E4: java/commun/service/AuditService.java java/commun/workflow/MoteurStatuts.java (appel à l'audit) | F4: P2 | G4: Mercredi après-midi
A5: BK0-09 | B5: Back | C5: Tableau de bord (données) | D5: /tableau-de-bord : chiffres clés par rôle, calculés sur les tables existantes (0 si vide). | E5: java/commun/controller/TableauDeBordController.java (/tableau-de-bord) java/commun/service/TableauDeBordService.java | F5: P1 / P2 | G5: Jeudi matin
A6: FR0-09 | B6: Front | C6: Tableau de bord + cloche | D6: dashboard/accueil : cartes de chiffres par rôle (données d'exemple puis branchement), cloche avec compteur. | E6: templates/dashboard/accueil.html templates/fragments/entete.html (cloche) | F6: P1 / P2 | G6: Mercredi / jeudi

Sheet 11. Tests & Soutenance
A1: ID | B1: Équipe | C1: Tâche | D1: Détails (faisable sans attendre personne) | E1: Dossier / fichiers | F1: Priorité | G1: Jour conseillé | H1: Status | I1: Fait par
A2: BK1-08 | B2: Back | C2: Tests du bloc 1 | D2: Transitions autorisées OK, interdites refusées, manager isolé à son département. | E2: test/besoin/BesoinWorkflowTests.java test/besoin/BesoinControllerTests.java | F2: P1 | G2: Jeudi matin
A3: BK2-07 | B3: Back | C3: Tests du bloc 2 | D3: Candidat réutilisé, double candidature refusée, offre expirée invisible, évaluateur non assigné refusé. | E3: test/recrutement/CandidatureServiceTests.java test/recrutement/EvaluationServiceTests.java | F3: P1 | G3: Jeudi matin
A4: BK3-08 | B4: Back | C4: Tests blocs 3 et 4 | D4: Embauche crée tout, échec = rien créé, CE → CDD → CDI conservé, chevauchement refusé, matricule unique, employé ne voit que son dossier. | E4: test/embauche/EmbaucheServiceTests.java test/embauche/ContratServiceTests.java test/embauche/MatriculeServiceTests.java | F4: P1 | G4: Jeudi matin
A5: BK0-10 | B5: Back | C5: Relecture sécurité | D5: Chaque URL testée avec chaque rôle, upload, pas de données sensibles dans les logs. | E5: test/commun/SecuriteTests.java | F5: P1 | G5: Jeudi après-midi
A6: FR0-11 | B6: Front | C6: CSRF + console propre | D6: Tous les formulaires envoient le jeton CSRF, aucune erreur console. | E6: templates/**/*.html (tous les formulaires : th:action) | F6: P1 | G6: Jeudi
A7: DS1-10 | B7: Design | C7: Revue écrans réels FR0 / FR2 | D7: Lister les écarts avec les maquettes par importance. | E7: Feuille : notes sous la tâche (ou TODO.md) | F7: P1 | G7: Jeudi
A8: DS2-07 | B8: Design | C8: Revue écrans réels FR1 / FR2 + test utilisateur | D8: Faire faire le scénario à 2 personnes extérieures. | E8: Feuille : notes sous la tâche (ou TODO.md) | F8: P1 | G8: Jeudi
A9: FR0-10 | B9: Front | C9: Corrections Design + responsive bloc 1 | D9: Gabarit et pages du bloc 1 sur téléphone. | E9: templates/fragments/*.html templates/besoins/, postes/ static/css/style.css | F9: P1 | G9: Jeudi après-midi
A10: FR1-08 | B10: Front | C10: Corrections Design + responsive bloc 2 | D10: Pages offres, carrières, candidatures sur téléphone. | E10: templates/public/, offres/, candidatures/, entretiens/, evaluations/ static/css/recrutement.css | F10: P1 | G10: Jeudi après-midi
A11: FR2-08 | B11: Front | C11: Corrections Design + responsive blocs 3-4 | D11: Frises et tableaux larges défilent ou passent en cartes. | E11: templates/propositions/, employes/, contrats/, onboarding/ static/css/rh.css | F11: P1 | G11: Jeudi après-midi
A12: T-09 | B12: Tous | C12: Gel des fonctionnalités | D12: Après jeudi 16h : uniquement corrections. | E12: — | F12: P1 | G12: Jeudi 16h
A13: T-10 | B13: Tous | C13: Tester le scénario complet | D13: Scénario section 11 de TODO.md, noter les bugs. | E13: TODO.md section 11 (scénario) + bugs notés dans la feuille | F13: P1 | G13: Jeudi 16h-18h
... A18: T-11 | B18: Tous | C18: Données de démo finales + répétition | D18: Jeu de données propre, répétition de la démo. | E18: java/*/demo/DonneesDemo*.java | F18: P1 | G18: Vendredi matin
A19: T-12 | B19: Tous | C19: Rendu et soutenance | E19: — | F19: P1 | G19: Vendredi
